<?xml version="1.0" ?>
<!-- =================================================================================== -->
<!-- |    This document was autogenerated by xacro from krytn.xacro.urdf               | -->
<!-- |    EDITING THIS FILE BY HAND IS NOT RECOMMENDED                                 | -->
<!-- =================================================================================== -->
<robot name="krytn">
  <!-- see https://secure.wikimedia.org/wikipedia/en/wiki/List_of_moment_of_inertia_tensors -->
  <link name="base_footprint"/>
  <joint name="base_footprint_joint" type="fixed">
    <parent link="base_footprint"/>
    <child link="base_link"/>
    <origin rpy="0 0 0" xyz="0 0 0.1"/>
  </joint>
  <!-- Base Link -->
  <link name="base_link">
    <origin rpy="0 0 0" xyz="-0.25 0 0.03"/>
    <visual>
      <origin rpy="0 0 0" xyz="-0.11 0 -0.029000000000000012"/>
      <geometry>
        <mesh filename="model://krytn/meshes/magni_body.dae"/>
      </geometry>
    </visual>
    <collision>
      <origin rpy="0 0 0" xyz="-0.11 0 0.05099999999999999"/>
      <geometry>
        <box size="0.398 0.268 0.160"/>
      </geometry>
    </collision>
    <collision>
      <origin rpy="0 0 0" xyz="-0.136 0 0.148"/>
      <geometry>
        <box size="0.375 0.268 0.034"/>
      </geometry>
    </collision>
    <collision>
      <origin rpy="0 0 0" xyz="-0.279 0.169 0.0059999999999999915"/>
      <geometry>
        <box size="0.1 0.07 0.07"/>
      </geometry>
    </collision>
    <collision>
      <origin rpy="0 0 0" xyz="-0.279 -0.169 0.0059999999999999915"/>
      <geometry>
        <box size="0.1 0.07 0.07"/>
      </geometry>
    </collision>
    <inertial>
      <mass value="10.0"/>
      <origin rpy="0 0 0" xyz="-0.15 0 0.03"/>
      <inertia ixx="0.059450809553" ixy="0.0" ixz="0.0" iyy="0.150753273032" iyz="0.0" izz="0.17270409758500002"/>
    </inertial>
  </link>
  <gazebo reference="base_link">
    <mu>0.1</mu>
    <mu1>0.1</mu1>
    <mu2>0.1</mu2>
    <slip1>0</slip1>
    <slip2>0</slip2>
  </gazebo>
  <link name="left_wheel">
    <collision>
      <origin rpy="0 1.5707963267948966 0" xyz="0.033 0 0"/>
      <geometry>
        <cylinder length="0.01" radius="0.1"/>
      </geometry>
    </collision>
    <visual>
      <origin rpy="0 0.0 0" xyz="-0.071 0 0"/>
      <geometry>
        <mesh filename="model://krytn/meshes/front_wheel.dae"/>
      </geometry>
    </visual>
    <inertial>
      <mass value="1.34"/>
      <origin rpy="0 1.5707963267948966 0" xyz="0 0 0"/>
      <inertia ixx="0.003629165215000001" ixy="0.0" ixz="0.0" iyy="0.003629165215000001" iyz="0.0" izz="0.006700000000000001"/>
    </inertial>
  </link>
  <joint name="left_wheel_joint" type="continuous">
    <axis rpy="0 0 0" xyz="1 0 0"/>
    <parent link="base_link"/>
    <child link="left_wheel"/>
    <origin rpy="0 0 1.5707963267948966" xyz="0 0.163 0"/>
    <dynamics damping="0.2" friction="0.8"/>
  </joint>
  <gazebo reference="left_wheel">
    <mu>0.5</mu>
    <mu1>0.5</mu1>
    <mu2>0.5</mu2>
    <minDepth>0.005</minDepth>
    <kp>1e8</kp>
  </gazebo>
  <link name="right_wheel">
    <collision>
      <origin rpy="0 1.5707963267948966 0" xyz="-0.033 0 0"/>
      <geometry>
        <cylinder length="0.01" radius="0.1"/>
      </geometry>
    </collision>
    <visual>
      <origin rpy="0 -3.141592653589793 0" xyz="0.071 0 0"/>
      <geometry>
        <mesh filename="model://krytn/meshes/front_wheel.dae"/>
      </geometry>
    </visual>
    <inertial>
      <mass value="1.34"/>
      <origin rpy="0 1.5707963267948966 0" xyz="0 0 0"/>
      <inertia ixx="0.003629165215000001" ixy="0.0" ixz="0.0" iyy="0.003629165215000001" iyz="0.0" izz="0.006700000000000001"/>
    </inertial>
  </link>
  <joint name="right_wheel_joint" type="continuous">
    <axis rpy="0 0 0" xyz="1 0 0"/>
    <parent link="base_link"/>
    <child link="right_wheel"/>
    <origin rpy="0 0 1.5707963267948966" xyz="0 -0.163 0"/>
    <dynamics damping="0.2" friction="0.8"/>
  </joint>
  <gazebo reference="right_wheel">
    <mu>0.5</mu>
    <mu1>0.5</mu1>
    <mu2>0.5</mu2>
    <minDepth>0.005</minDepth>
    <kp>1e8</kp>
  </gazebo>
  <link name="left_caster_wheel">
    <origin rpy="0 0 0" xyz="-0.37 0.169 -0.060000000000000005"/>
    <collision>
      <origin rpy="0 0 0" xyz="-0.27 0.169 -0.060000000000000005"/>
      <geometry>
        <sphere radius="0.04"/>
      </geometry>
    </collision>
    <visual>
      <origin rpy="0 0 3.141592653589793" xyz="-0.25 0.169 0"/>
      <geometry>
        <mesh filename="model://krytn/meshes/caster_wheel.dae"/>
      </geometry>
    </visual>
    <!-- removing inertia of caster wheels so that base inertial is not tilted. 
      <xacro:cylinder_inertial_with_origin radius="${wheel_r}" length="0.05" mass="3.34">
          <origin xyz="0 0 0" rpy="0 ${pi/2} 0" />
       </xacro:cylinder_inertial_with_origin> 
       -->
  </link>
  <joint name="left_caster_wheel_joint" type="fixed">
    <parent link="base_link"/>
    <child link="left_caster_wheel"/>
  </joint>
  <gazebo reference="left_caster_wheel">
    <mu>0.1</mu>
    <mu1>0.1</mu1>
    <mu2>0.1</mu2>
    <slip1>0</slip1>
    <slip2>0</slip2>
  </gazebo>
  <link name="right_caster_wheel">
    <origin rpy="0 0 0" xyz="-0.37 -0.169 -0.060000000000000005"/>
    <collision>
      <origin rpy="0 0 0" xyz="-0.27 -0.169 -0.060000000000000005"/>
      <geometry>
        <sphere radius="0.04"/>
      </geometry>
    </collision>
    <visual>
      <origin rpy="0 0 3.141592653589793" xyz="-0.25 -0.169 0"/>
      <geometry>
        <mesh filename="model://krytn/meshes/caster_wheel.dae"/>
      </geometry>
    </visual>
    <!-- removing inertia of caster wheels so that base inertial is not tilted. 
      <xacro:cylinder_inertial_with_origin radius="${wheel_r}" length="0.05" mass="3.34">
          <origin xyz="0 0 0" rpy="0 ${pi/2} 0" />
       </xacro:cylinder_inertial_with_origin> 
       -->
  </link>
  <joint name="right_caster_wheel_joint" type="fixed">
    <parent link="base_link"/>
    <child link="right_caster_wheel"/>
  </joint>
  <gazebo reference="right_caster_wheel">
    <mu>0.1</mu>
    <mu1>0.1</mu1>
    <mu2>0.1</mu2>
    <slip1>0</slip1>
    <slip2>0</slip2>
  </gazebo>
  <!-- add a laser -->
  <link name="laser_link">
    <visual name="visual">
      <geometry>
        <cylinder length="0.05" radius="0.05"/>
      </geometry>
    </visual>
    <collision>
      <geometry>
        <cylinder length="0.05" radius="0.05"/>
      </geometry>
    </collision>
  </link>
  <joint name="laser_link_joint" type="fixed">
    <parent link="base_link"/>
    <child link="laser_link"/>
    <origin rpy="0 0 0" xyz="-0.093 0 0.198"/>
  </joint>
  <ros2_control name="GazeboSystem" type="system">
    <hardware>
      <plugin>gazebo_ros2_control/GazeboSystem</plugin>
    </hardware>
    <joint name="left_wheel_joint">
      <command_interface name="velocity">
        <param name="min">-1</param>
        <param name="max">1</param>
      </command_interface>
      <state_interface name="position"/>
      <state_interface name="velocity"/>
    </joint>
    <joint name="right_wheel_joint">
      <command_interface name="velocity">
        <param name="min">-1</param>
        <param name="max">1</param>
      </command_interface>
      <state_interface name="position"/>
      <state_interface name="velocity"/>
    </joint>
  </ros2_control>
  <gazebo>
    <plugin filename="libgazebo_ros2_control.so" name="gazebo_ros2_control">
      <parameters>/workspace/dev_ws/src/warehouse_robot_spawner_pkg/config/copy_of_diff_con.yaml</parameters>
    </plugin>
  </gazebo>
</robot>
